Workbook

Sheet AliasFuncsLvl0
A1: ignore | B1: funcId | C1: name | D1: type | E1: value | F1: aliasFuncArg | G1: arg1 | H1: arg2 | I1: arg3
A5: TRUE | B5: This row start parsing
B6: HardGood | C6: $type | D6: str | E6: GameplayConfigs.HardGoodConfig
C7: amount | D7: num | E7: %amount%
B9: Example3.4_tableFunc | C9: field1 | D9: num | E9: %arg1%
C10: field2 | D10: str | E10: %arg2%
C11: field3 | D11: bool | E11: %arg3%
B13: FuncWith2Args | C13: field1 | D13: num | E13: %arg1%
C14: field2 | D14: num | E14: %arg2%
B15: FuncWithFunc | C15: field1 | D15: num | E15: %arg1%
C16: field2 | D16: SoftGood | E16: amount | F16: %amount%
B17: FuncWithNextLvlSheet | C17: field1 | D17: ref | E17: FuncWithNextLvlSheet_field1
B19: FuncWithNextLvlSheetAndArg | C19: field1 | D19: ref | E19: FuncWithNextLvlSheetAndArg_field1
B21: FuncWithNextLvlSheetAndFuncWithArg | C21: fiel1 | D21: ref | E21: FuncWithNextLvlSheetAndFuncWithArg_field1
B22: FuncWithNextLvlSheetAndFuncWithWrapArg | C22: fiel1 | D22: ref | E22: FuncWithNextLvlSheetAndFuncWithWrapArg_field1
B24: ExampleExcelAliasFuncWithAnonymArg1 | C24: field1 | D24: num | E24: %arg1%
C25: field2 | D25: num | E25: %arg2%
C26: field3 | D26: num | E26: %arg3%
B28: ExampleExcelAliasFuncWithAnonymArg2 | C28: field1 | D28: num | E28: %arg1%
C29: field2 | D29: ExampleExcelAliasFuncWithAnonymArg1 | G29: %arg1% | H29: %arg2% | I29: %arg3%

Sheet AliasFuncsLvl1
A1: ignore | B1: funcId | C1: name | D1: type | E1: value | F1: aliasFuncArg | G1: arg1 | H1: arg2 | I1: arg3
A5: TRUE | B5: This row start parsing
B7: FuncWithNextLvlSheet_field1 | C7: field2 | D7: str | E7: test
C8: field3 | D8: str | E8: test
B10: FuncWithNextLvlSheetAndArg_field1 | C10: field2 | D10: str | E10: %arg_value%
C11: field3 | D11: str | E11: test
B13: FuncWithNextLvlSheetAndFuncWithArg_field1 | C13: field1 | D13: SoftGood | E13: amount | F13: %amount%
B14: FuncWithNextLvlSheetAndFuncWithWrapArg_field1 | C14: field1 | D14: SoftGood | E14: amount | F14: %wrap_amount_arg%

Sheet Lvl0
A1: ignore | B1: id | C1: name | D1: type | E1: value | F1: aliasFuncArg | G1: arg1 | H1: arg2 | I1: arg3
A5: TRUE | B5: This row start parsing
A7: TRUE | B7: Example1. Parsing target json
B8: example1 | C8: name | D8: str | E8: Igor
C9: surname | D9: str | E9: Skladchikov
C10: age | D10: num | E10: 28
C11: address | D11: ref | E11: example1_adress
A14: TRUE | B14: Example2. Types variation
B15: example2 | C15: stringField | D15: str | E15: text
C16: numberField | D16: num | E16: 123
C17: booleanField | D17: bool | E17: TRUE
C18: nullField | D18: null
C19: objectField | D19: ref | E19: example2_objField
C20: arrayField | D20: arr | E20: example2_arrField
C21: objArrayField | D21: arr | E21: example2_objArrayField
A24: TRUE | B24: Example3 Alias function
A25: TRUE | B25: Example3.1 Alias function. Semantics without alias func
B27: example3.1 | C27: good1 | D27: ref | E27: example3.1_good1
C28: good2 | D28: ref | E28: example3.1_good2
C29: goods | D29: arr | E29: example3.1_goods
A32: TRUE | B32: Example3.2 Alias function. Semantics with alias func
B34: example3.2 | C34: good1 | D34: HardGood | E34: amount | F34: 100
C35: good2 | D35: HardGood | E35: amount | F35: 350
C36: goods | D36: arr | E36: example3.2_goods
A39: TRUE | B39: Example3.3 Alias function. Json and table alias functions
B41: example3.3 | C41: tableAliasFuncField | D41: HardGood | E41: amount | F41: 1500
C42: jsonAliasFuncField | D42: SoftGood | E42: amount | F42: 1500
A45: TRUE | B45: Example3.3.1 Alias function. Json alias funcetions. Arg position variations
B46: example3.3.1 | C46: argsVariations | D46: jsonFuncArgsPositionVariations | E46: amount | F46: 1000
A48: TRUE | B48: Example 3.4 Alias function. Anonym args
B50: example3.4 | C50: tableFunc | D50: Example3.4_tableFunc | G50: 200 | H50: text | I50: TRUE
C51: jsonFunc | D51: Example3.4_jsonFunc | G51: 200 | H51: text | I51: TRUE
C52: jsonFuncWithTypedArg | D52: Example3.4_jsonFuncWithTypedArg | E52: amount | F52: 1500 | H52: text | I52: FALSE
A56: TRUE | B56: Example4. Other
A58: TRUE | B58: ignoredFeature1
A59: TRUE | B59: ignoredFeature2
A60: FALSE | B60: season | C60: type | D60: str | E60: TypeX
C61: fiel1 | D61: num | E61: 10
C62: field1_1 | D62: null
C63: field2 | D63: ref | E63: seasonField1
...

Sheet Lvl1
A1: ignore | B1: id | C1: name | D1: type | E1: value | F1: aliasFuncArg | G1: arg1 | H1: arg2 | I1: arg3
A5: TRUE | B5: =Lvl0!B5 -> This row start parsing
A7: TRUE | B7: =Lvl0!B7 -> Example1. Parsing target json
B8: example1_adress | C8: country | D8: str | E8: Russian
C9: city | D9: str | E9: Saint Petersburg
A12: TRUE | B12: =Lvl0!B14 -> Example2. Types variation
B13: example2_objField | C13: subfield1 | D13: str | E13: text1
C14: subfield2 | D14: num | E14: 12345
B16: example2_arrField | D16: str | E16: item1
D17: str | E17: item2
D18: str | E18: item3
D19: str | E19: item4
D20: str | E20: item5
B21: example2_objArrayField | D21: ref | E21: example2_objArrayField_item1
D22: ref | E22: example2_objArrayField_item2
D23: ref | E23: example2_objArrayField_item3
A26: TRUE | B26: =Lvl0!B24 -> Example3 Alias function
A27: TRUE | B27: =Lvl0!B25 -> Example3.1 Alias function. Semantics without alias func
B29: example3.1_good1 | C29: $type | D29: str | E29: GameplayConfigs.HardGoodConfig
C30: amount | D30: num | E30: 100
B31: example3.1_good2 | C31: $type | D31: str | E31: GameplayConfigs.HardGoodConfig
C32: amount | D32: num | E32: 350
B33: example3.1_goods | D33: ref | E33: example3.1_goods_item1
D34: ref | E34: example3.1_goods_item2
A36: TRUE | B36: =Lvl0!B32 -> Example3.2 Alias function. Semantics with alias func
B37: example3.2_goods | D37: HardGood | E37: amount | F37: 1250
D38: HardGood | E38: amount | F38: 500
A42: TRUE | B42: Example4. Other
B44: seasonField1 | C44: field1 | D44: str | E44: text1
B45: seasonField2 | C45: field1 | D45: str | E45: text1
C46: field2 | D46: str | E46: text2
B48: seasonField3Arr | D48: str | E48: arr1
D49: str | E49: arr2
B52: seasonField5Arr | D52: ref | E52: seasonField5Arr_item1
D53: ref | E53: seasonField5Arr_item2
B56: seasonEmptyArr
B59: seasonArrWithEmptyItems | D59: ref | E59: seasonArrWithEmptyItems_item1
D60: ref | E60: seasonArrWithEmptyItems_item2
B62: seasonEmptyField
B64: seasonDict | C64: $type | D64: str | E64: Common.GameplayConfigs.Player.Seasons.SeasonConfig
...

Sheet Lvl2
A1: ignore | B1: id | C1: name | D1: type | E1: value | F1: aliasFuncArg | G1: arg1 | H1: arg2 | I1: arg3
A5: TRUE | B5: ='Lvl1'!B5:XFD5 -> This row start parsing
A7: TRUE | B7: ='Lvl1'!B12:XFD12 -> Example2. Types variation
B8: example2_objArrayField_item1 | C8: subfield1 | D8: str | E8: text
C9: subfield2 | D9: num | E9: 12345
B11: example2_objArrayField_item2 | C11: subfield1 | D11: bool | E11: TRUE
C12: subfield2 | D12: bool | E12: FALSE
B14: example2_objArrayField_item3 | C14: subfield1 | D14: null
C15: subfield2 | D15: str | E15: text
A18: TRUE | B18: ='Lvl1'!B26 -> Example3 Alias function
A19: TRUE | B19: ='Lvl1'!B27 -> Example3.1 Alias function. Semantics without alias func
B21: example3.1_goods_item1 | C21: $type | D21: str | E21: GameplayConfigs.HardGoodConfig
C22: amount | D22: num | E22: 1250
B23: example3.1_goods_item2 | C23: $type | D23: str | E23: GameplayConfigs.HardGoodConfig
C24: amount | D24: num | E24: 500
O25: ==IF(ROWS(FILTER($R$52:$R$73,($M$52:$M$73=$C49)*($N$52:$N$73=$J49)))=0,"",FILTER($R$52:$R$73,($M$52:$M$73=$C49)*($N$52:$N$73=$J49)))
A28: TRUE | B28: Example4. Other
B30: seasonField5Arr_item1 | C30: field1 | D30: str | E30: text
C31: field2 | D31: num | E31: 123
B34: seasonField5Arr_item2 | C34: field3 | D34: str | E34: text
C35: field4 | D35: num | E35: 123
B38: seasonArrWithEmptyItems_item1
B39: seasonArrWithEmptyItems_item2
B41: seasonDict_item1 | C41: field1 | D41: str | E41: text
B42: seasonDict_item2 | C42: field2 | D42: num | E42: 456
A45: TRUE | B45: Example5. Semantic with filter formulas
A47: TRUE | B47: Titlte for stages number → | J47: stageNumer
B49: =_xlfn.CONCAT("stage",J49) -> stage0 | C49: $type | D49: str | E49: Common.GameplayConfigs.Player.Seasons.SeasonConfig+Stage | J49: 0
C50: tokens | D50: num | E50: {=_xlfn.TAKE(_xlfn._xlws.FILTER($S$54:$S$75,$N$54:$N$75=J50, TRUE), 1)} -> 50 | J50: =J49 -> 0
C51: basicReward | D51: {=_xlfn._xlws.FILTER($O$54:$O$75, ($M$54:$M$75=$C51)*($N$54:$N$75=$J51))} -> SeasonLootBoxReward | G51: {=_xlfn._xlws.FILTER($P$54:$P$75, (ISBLANK($P$54:$P$75)=FALSE)*($M$54:$M$75=$C51)*($N$54:$N$75=$J51), "")} -> FALSE | H51: {=_xlfn._xlws.FILTER($Q$54:$Q$75, (ISBLANK($Q$54:$Q$75)=FALSE)*($M$54:$M$75=$C51)*($N$54:$N$75=$J51), "")} -> LootBoxSilver | I51: {=_xlfn._xlws.FILTER($R$54:$R$75, (ISBLANK($R$54:$R$75)=FALSE)*($M$54:$M$75=$C51)*($N$54:$N$75=$J51), "")} | J51: =J50 -> 0
C52: passReward | D52: {=_xlfn._xlws.FILTER($O$54:$O$75, ($M$54:$M$75=$C52)*($N$54:$N$75=$J52))} -> SeasonLootBoxReward | G52: {=_xlfn._xlws.FILTER($P$54:$P$75, (ISBLANK($P$54:$P$75)=FALSE)*($M$54:$M$75=$C52)*($N$54:$N$75=$J52), "")} -> FALSE | H52: {=_xlfn._xlws.FILTER($Q$54:$Q$75, (ISBLANK($Q$54:$Q$75)=FALSE)*($M$54:$M$75=$C52)*($N$54:$N$75=$J52), "")} -> LootBoxGold | I52: {=_xlfn._xlws.FILTER($R$54:$R$75, (ISBLANK($R$54:$R$75)=FALSE)*($M$54:$M$75=$C52)*($N$54:$N$75=$J52), "")} | J52: =J51 -> 0 | O52: For parsing
N53: stage | O53: AliasFuncName | P53: arg1 | Q53: arg2 | R53: arg3 | S53: Tokens | T53: isPremium | U53: Type | V53: Content | W53: Count
B54: =_xlfn.CONCAT("stage",J54) -> stage1 | C54: $type | D54: str | E54: Common.GameplayConfigs.Player.Seasons.SeasonConfig+Stage | J54: 1 | M54: basicReward | N54: 0 | O54: SeasonLootBoxReward | P54: =T54 -> FALSE | Q54: =V54 -> LootBoxSilver | S54: 50 | T54: FALSE | U54: LootBox | V54: LootBoxSilver
C55: tokens | D55: num | E55: {=_xlfn.TAKE(_xlfn._xlws.FILTER($S$54:$S$75,$N$54:$N$75=J55, TRUE), 1)} -> 150 | J55: =J54 -> 1 | M55: passReward | N55: 0 | O55: SeasonLootBoxReward | P55: =T55 -> FALSE | Q55: =V55 -> LootBoxGold | T55: FALSE | U55: LootBox | V55: LootBoxGold
C56: basicReward | D56: {=_xlfn._xlws.FILTER($O$54:$O$75, ($M$54:$M$75=$C56)*($N$54:$N$75=$J56))} -> SeasonWheelTicketsReward | G56: {=_xlfn._xlws.FILTER($P$54:$P$75, (ISBLANK($P$54:$P$75)=FALSE)*($M$54:$M$75=$C56)*($N$54:$N$75=$J56), "")} -> FALSE | H56: {=_xlfn._xlws.FILTER($Q$54:$Q$75, (ISBLANK($Q$54:$Q$75)=FALSE)*($M$54:$M$75=$C56)*($N$54:$N$75=$J56), "")} -> Basic | I56: {=_xlfn._xlws.FILTER($R$54:$R$75, (ISBLANK($R$54:$R$75)=FALSE)*($M$54:$M$75=$C56)*($N$54:$N$75=$J56), "")} -> 1 | J56: =J55 -> 1 | M56: basicReward | N56: 1 | O56: SeasonWheelTicketsReward | P56: =T56 -> FALSE | Q56: =V56 -> Basic | R56: =W56 -> 1 | S56: 150 | T56: FALSE | U56: WheelTickets | V56: Basic | W56: 1
C57: passReward | D57: {=_xlfn._xlws.FILTER($O$54:$O$75, ($M$54:$M$75=$C57)*($N$54:$N$75=$J57))} -> SeasonCoreRandomBoosterReward | G57: {=_xlfn._xlws.FILTER($P$54:$P$75, (ISBLANK($P$54:$P$75)=FALSE)*($M$54:$M$75=$C57)*($N$54:$N$75=$J57), "")} -> FALSE | H57: {=_xlfn._xlws.FILTER($Q$54:$Q$75, (ISBLANK($Q$54:$Q$75)=FALSE)*($M$54:$M$75=$C57)*($N$54:$N$75=$J57), "")} -> SeasonRandomBooster | I57: {=_xlfn._xlws.FILTER($R$54:$R$75, (ISBLANK($R$54:$R$75)=FALSE)*($M$54:$M$75=$C57)*($N$54:$N$75=$J57), "")} -> 2 | J57: =J56 -> 1 | M57: passReward | N57: 1 | O57: SeasonCoreRandomBoosterReward | P57: =T57 -> FALSE | Q57: =V57:V75 -> SeasonRandomBooster | R57: =W57 -> 2 | T57: FALSE | U57: RandBoosters | V57: SeasonRandomBooster | W57: 2
M58: basicReward | N58: 2 | O58: SeasonCoreRandomBoosterReward | P58: =T58 -> FALSE | Q58: =V58:V76 -> SeasonRandomBooster | R58: =W58 -> 2 | S58: 250 | T58: FALSE | U58: RandBoosters | V58: SeasonRandomBooster | W58: 2
B59: =_xlfn.CONCAT("stage",J59) -> stage2 | C59: $type | D59: str | E59: Common.GameplayConfigs.Player.Seasons.SeasonConfig+Stage | J59: 2 | M59: passReward | N59: 2 | O59: SeasonHardReward | P59: =T59 -> FALSE | Q59: =W59 -> 100 | T59: FALSE | U59: HardCurrency | W59: 100
C60: tokens | D60: num | E60: {=_xlfn.TAKE(_xlfn._xlws.FILTER($S$54:$S$75,$N$54:$N$75=J60, TRUE), 1)} -> 250 | J60: =J59 -> 2 | M60: basicReward | N60: 3 | O60: SeasonHardReward | P60: =T60 -> FALSE | Q60: =W60 -> 500 | S60: 300 | T60: FALSE | U60: HardCurrency | W60: 500
C61: basicReward | D61: {=_xlfn._xlws.FILTER($O$54:$O$75, ($M$54:$M$75=$C61)*($N$54:$N$75=$J61))} -> SeasonCoreRandomBoosterReward | G61: {=_xlfn._xlws.FILTER($P$54:$P$75, (ISBLANK($P$54:$P$75)=FALSE)*($M$54:$M$75=$C61)*($N$54:$N$75=$J61), "")} -> FALSE | H61: {=_xlfn._xlws.FILTER($Q$54:$Q$75, (ISBLANK($Q$54:$Q$75)=FALSE)*($M$54:$M$75=$C61)*($N$54:$N$75=$J61), "")} -> SeasonRandomBooster | I61: {=_xlfn._xlws.FILTER($R$54:$R$75, (ISBLANK($R$54:$R$75)=FALSE)*($M$54:$M$75=$C61)*($N$54:$N$75=$J61), "")} -> 2 | J61: =J60 -> 2 | M61: passReward | N61: 3 | O61: SeasonLootBoxReward | P61: =T61 -> FALSE | Q61: =V61 -> LootBoxSilver | T61: FALSE | U61: LootBox | V61: LootBoxSilver
...
